<?xml version="1.0"?>
<robot xmlns:xacro="http://www.ros.org/wiki/xacro">

  <xacro:property name="M_PI" value="3.1415926535897931" />

  <xacro:macro name="ewellix_lift" params="
    name
    tf_prefix
    use_fake_hardware:=false
    com_port:=/dev/ttyUSB0
    baudrate:=34800
  ">
    <!-- TODO work on abstracting this xacro to work for both 500 and 700mm lifts (I'll give it a shot -Mike)-->
    <!-- TODO is this a good collision? (No, it wasn't, raw meshes in general do not make good collision objects -Mike)-->
    <!-- TODO figure out how to retract the top link entirely without it colliding through the base. Consider splitting the top into two pieces with a mimic joint (Will do -Mike)-->

    <!-- Sure hope this is all works in SI units... -Mike-->
    
    <!--BASE-->
    <link name="${tf_prefix}ewellix_lift_base_link">
      <inertia>
        <mass value="1.7383784"/>
        <inertia ixx="5.7788770e-03" ixy="0" ixz="0" iyy="7.0031715e-03" iyz="0" izz="1.2717018e-02"/>
      </inertia>
      <visual>
        <geometry>
          <box size="0.220 0.200 0.015"/>
        </geometry>
      </visual>
      <collision>
        <geometry>
          <box size="0.220 0.200 0.015"/>
        </geometry>
      </collision>
    </link>

    <!--LOWER-->
    <link name="${tf_prefix}ewellix_lift_lower_link">
      <!-- TODO -Mike
      <inertia>
        <mass value=""/>
        <inertia ixx="" ixy="" ixz="" iyy="" iyz="" izz=""/>
      </inertia>
      -->
      <visual>
        <geometry>
          <mesh filename= "file://$(find ewellix_liftkit_description)/meshes/visual/lift_low.dae"/>
        </geometry>
      </visual>
      <collision>
        <geometry>
          <box size="0.163 0.163 0.480"/>
        </geometry>
      </collision>
    </link>
    
    <!--BASE TO LOWER (FIXED)-->
    <joint name="base_to_lower" type="fixed">
      <parent link="${tf_prefix}ewellix_lift_base_link"/>
      <child link="${tf_prefix}ewellix_lift_lower_link"/>
      <origin xyz="0 0 0.2475" rpy="0 0 0"/>
    </joint>

    <!--MIDDLE-->
    <link name="${tf_prefix}ewellix_lift_middle_link">
      <!-- TODO -Mike
      <inertia>
        <mass value=""/>
        <inertia ixx="" ixy="" ixz="" iyy="" iyz="" izz=""/>
      </inertia>
      -->
      <visual>
        <geometry>
          <mesh filename= "file://$(find ewellix_liftkit_description)/meshes/visual/lift_mid.dae"/>
        </geometry>
      </visual>
      <collision>
        <geometry>
          <box size="0.146 0.146 0.483"/>
        </geometry>
      </collision>
    </link>

    <!--HIGHER-->
    <link name="${tf_prefix}ewellix_lift_higher_link">
      <!-- TODO -Mike
      <inertia>
        <mass value=""/>
        <inertia ixx="" ixy="" ixz="" iyy="" iyz="" izz=""/>
      </inertia>
      -->
      <visual>
        <geometry>
          <mesh filename= "file://$(find ewellix_liftkit_description)/meshes/visual/lift_high.dae"/>
        </geometry>
      </visual>
      <collision>
        <geometry>
          <box size="0.129 0.129 0.488"/>
        </geometry>
      </collision>
    </link>

    <!--LOWER TO HIGHER (PRIS)-->
    <joint name="lower_to_higher" type="prismatic">
      <parent link="${tf_prefix}ewellix_lift_lower_link"/>
      <child link="${tf_prefix}ewellix_lift_higher_link"/>
      <origin xyz="0 0 0.0454" rpy="0 0 0"/>
      <axis xyz="0 0 1"/>
      <limit lower="0" upper="0.7" effort="1000" velocity="1"/>
    </joint>

    <!--MIDDLE MIMIC HIGHER (PRIS MIMIC)-->
    <joint name="middle_mimic_higher" type="prismatic">
      <parent link="${tf_prefix}ewellix_lift_higher_link"/>
      <child link="${tf_prefix}ewellix_lift_middle_link"/>
      <origin xyz="0 0 -0.0222" rpy="0 0 0"/>
      <axis xyz="0 0 -1"/>
      <limit lower="0" upper="0.351" effort="1000" velocity="1"/>
      <mimic joint="lower_to_higher" multiplier="0.5" offset="0"/>
    </joint>

    <!--TOP-->
    <link name="${tf_prefix}ewellix_lift_top_link">
      <!-- TODO -Mike
      <inertia>
        <mass value=""/>
        <inertia ixx="" ixy="" ixz="" iyy="" iyz="" izz=""/>
      </inertia>
      -->
      <visual>
        <geometry>
          <box size="0.200 0.220 0.015"/>
        </geometry>
      </visual>
      <collision>
        <geometry>
          <box size="0.200 0.220 0.015"/>
        </geometry>
      </collision>
    </link>

    <!--HIGHER TO TOP (FIXED)-->
    <joint name="higher_to_top" type="fixed">
      <parent link="${tf_prefix}ewellix_lift_higher_link"/>
      <child link="${tf_prefix}ewellix_lift_top_link"/>
      <origin xyz="0 0 0.2515" rpy="0 0 0"/>
    </joint>
    
    <xacro:include filename="$(find ewellix_liftkit_description)/urdf/ewellix_liftkit.ros2_control.xacro" />
    <xacro:ewellix_liftkit_ros2_control
      name="${name}"
      use_fake_hardware="${use_fake_hardware}"
      tf_prefix="${tf_prefix}"
      com_port="${com_port}"
      baudrate="${baudrate}"
    />


  </xacro:macro>
  
</robot>