<?xml version="1.0"?>

<robot xmlns:xacro="http://ros.org/wiki/xacro" name="simple_rail">
  
  <link name="base_link">
    <visual>
      <origin xyz="-1.18125 0 0" rpy="0 0 0"/>
      <geometry>
        <box size="2.3625 0.153 0.09"/>
      </geometry>
    </visual>
  </link>

  <link name="carriage">
    <visual>
      <origin xyz="-0.1115 0 0.0565" rpy="0 0 0"/>
      <geometry>
        <box size="0.223 0.223 0.023"/>
      </geometry>
    </visual>
  </link>
  
  <joint name="base_to_carriage" type="prismatic">
    <origin xyz="-0.223 0 0" rpy="0 0 3.14159"/>
    <parent link="base_link"/>
    <child link="carriage"/>
    <limit effort="1000" velocity="0.197" lower="0" upper="2.1395"/>

  </joint>
  
</robot>

